<?xml version="1.0" encoding="utf-8"?>
<!-- This URDF was automatically created by SolidWorks to URDF Exporter! Originally created by
Stephen Brawner (brawner@gmail.com) 
     Commit Version: 1.6.0-4-g7f85cfe  Build Version: 1.6.7995.38578
     For more information, please see http://wiki.ros.org/sw_urdf_exporter -->
<robot
  name="myurdf_fix">
  <link name='base_footprint' />
  <joint name='base_footprint_joint' type='fixed'>
    <origin xyz="0 0 0" rpy="0 0 0" />
    <parent link='base_footprint' />
    <child link='base_link' />
  </joint>
  <link name='laser_link' />
  <joint name='laser_joint' type='fixed'>
    <origin xyz="0 0 0.15" rpy="0 0 0" />
    <parent link='base_link' />
    <child link='laser_link' />
  </joint>
  <link name='camera_link' />
  <joint name='camera_joint' type='fixed'>
    <origin xyz="0 0 0.4" rpy="0 0 3.1415926" />
    <parent link='base_link' />
    <child link='camera_link' />
  </joint>
  <link
    name="base_link">
    <inertial>
      <origin
        xyz="-0.00134195390733982 0.00857867844676492 -0.00415434685325502"
        rpy="0 0 0" />
      <mass
        value="1.95577438123772" />
      <inertia
        ixx="0.0154639028570486"
        ixy="4.36382890736415E-05"
        ixz="5.90932548570652E-11"
        iyy="0.0133714917548376"
        iyz="2.29370931819144E-06"
        izz="0.0286717017267533" />
    </inertial>
    <visual>
      <origin
        xyz="0 0 0"
        rpy="0 0 0" />
      <geometry>
        <mesh
          filename="package://my_tf_tree/meshes/base_link.obj" />
      </geometry>
      <material
        name="">
        <color
          rgba="0.898039215686275 0.917647058823529 0.929411764705882 1" />
      </material>
    </visual>
    <collision>
      <origin
        xyz="0 0 0"
        rpy="0 0 0" />
      <geometry>
        <mesh
          filename="package://my_tf_tree/meshes/base_link.obj" />
      </geometry>
    </collision>
  </link>
  <link
    name="front_right_steering">
    <inertial>
      <origin
        xyz="0.00801776215731034 -0.0117428465609573 0.000580924898174157"
        rpy="0 0 0" />
      <mass
        value="0.610591222095894" />
      <inertia
        ixx="0.000582629289495863"
        ixy="-4.99430083725306E-07"
        ixz="1.10358360622854E-05"
        iyy="0.000991102871531918"
        iyz="-8.35472068741382E-06"
        izz="0.000533386188927072" />
    </inertial>
    <visual>
      <origin
        xyz="0 0 0"
        rpy="0 0 0" />
      <geometry>
        <mesh
          filename="package://my_tf_tree/meshes/front_right_steering.obj" />
      </geometry>
      <material
        name="">
        <color
          rgba="0.647058823529412 0.619607843137255 0.588235294117647 1" />
      </material>
    </visual>
    <collision>
      <origin
        xyz="0 0 0"
        rpy="0 0 0" />
      <geometry>
        <mesh
          filename="package://my_tf_tree/meshes/front_right_steering.obj" />
      </geometry>
    </collision>
  </link>
  <joint
    name="front_right_steering_joint"
    type="continuous">
    <origin
      xyz="-0.23737 -0.21658 0.01281"
      rpy="1.5708 0 -2.1067" />
    <parent
      link="base_link" />
    <child
      link="front_right_steering" />
    <axis
      xyz="0 -1 0" />
  </joint>
  <link
    name="front_right_wheel">
    <inertial>
      <origin
        xyz="-1.36224666647811E-05 -0.00233860532400534 -1.278132998489E-05"
        rpy="0 0 0" />
      <mass
        value="0.265552463932757" />
      <inertia
        ixx="0.000257423769631664"
        ixy="4.21536341431832E-07"
        ixz="6.90830608456444E-07"
        iyy="0.00042589263687006"
        iyz="3.86659897806611E-07"
        izz="0.000257304300299443" />
    </inertial>
    <visual>
      <origin
        xyz="0 0 0"
        rpy="0 0 0" />
      <geometry>
        <mesh
          filename="package://my_tf_tree/meshes/front_right_wheel.obj" />
      </geometry>
      <material
        name="">
        <color
          rgba="0.776470588235294 0.756862745098039 0.737254901960784 1" />
      </material>
    </visual>
    <collision>
      <origin
        xyz="0 0 0"
        rpy="0 0 0" />
      <geometry>
        <mesh
          filename="package://my_tf_tree/meshes/front_right_wheel.obj" />
      </geometry>
    </collision>
  </link>
  <joint
    name="front_right_wheel_joint"
    type="continuous">
    <origin
      xyz="-0.0087483 -0.041 -0.0021067"
      rpy="-2.9038 -0.11023 -1.5975" />
    <parent
      link="front_right_steering" />
    <child
      link="front_right_wheel" />
    <axis
      xyz="0 1 0" />
  </joint>
  <link
    name="front_left_steering">
    <inertial>
      <origin
        xyz="0.00801776215571048 -0.0117428465598819 0.000580924897009727"
        rpy="0 0 0" />
      <mass
        value="0.610591222055897" />
      <inertia
        ixx="0.00058262928949571"
        ixy="-4.99430083842299E-07"
        ixz="1.10358360623182E-05"
        iyy="0.000991102871531828"
        iyz="-8.35472068740538E-06"
        izz="0.000533386188926846" />
    </inertial>
    <visual>
      <origin
        xyz="0 0 0"
        rpy="0 0 0" />
      <geometry>
        <mesh
          filename="package://my_tf_tree/meshes/front_left_steering.obj" />
      </geometry>
      <material
        name="">
        <color
          rgba="0.647058823529412 0.619607843137255 0.588235294117647 1" />
      </material>
    </visual>
    <collision>
      <origin
        xyz="0 0 0"
        rpy="0 0 0" />
      <geometry>
        <mesh
          filename="package://my_tf_tree/meshes/front_left_steering.obj" />
      </geometry>
    </collision>
  </link>
  <joint
    name="front_left_steering_joint"
    type="continuous">
    <origin
      xyz="0.23463 -0.21658 0.01281"
      rpy="1.5708 0 -0.53589" />
    <parent
      link="base_link" />
    <child
      link="front_left_steering" />
    <axis
      xyz="0 -1 0" />
  </joint>
  <link
    name="front_left_wheel">
    <inertial>
      <origin
        xyz="2.10718168858204E-07 -0.0153386053240053 0.00058132141354203"
        rpy="0 0 0" />
      <mass
        value="0.265552463932757" />
      <inertia
        ixx="0.000256670626601085"
        ixy="-2.43945488809238E-19"
        ixz="1.42301535138722E-19"
        iyy="0.00042589263687006"
        iyz="5.72012905204114E-07"
        izz="0.000258057443330023" />
    </inertial>
    <visual>
      <origin
        xyz="0 0 0"
        rpy="0 0 0" />
      <geometry>
        <mesh
          filename="package://my_tf_tree/meshes/front_left_wheel.obj" />
      </geometry>
      <material
        name="">
        <color
          rgba="0.898039215686275 0.917647058823529 0.929411764705882 1" />
      </material>
    </visual>
    <collision>
      <origin
        xyz="0 0 0"
        rpy="0 0 0" />
      <geometry>
        <mesh
          filename="package://my_tf_tree/meshes/front_left_wheel.obj" />
      </geometry>
    </collision>
  </link>
  <joint
    name="front_left_wheel_joint"
    type="continuous">
    <origin
      xyz="-0.02147 -0.040515 -0.0048072"
      rpy="-2.753 -0.90465 -1.8822" />
    <parent
      link="front_left_steering" />
    <child
      link="front_left_wheel" />
    <axis
      xyz="0 1 0" />
  </joint>
  <link
    name="back_right_steering">
    <inertial>
      <origin
        xyz="0.00801776215587333 -0.0117428465600048 0.000580924897084528"
        rpy="0 0 0" />
      <mass
        value="0.610591222059871" />
      <inertia
        ixx="0.00058262928949572"
        ixy="-4.99430083847526E-07"
        ixz="1.10358360622257E-05"
        iyy="0.00099110287153194"
        iyz="-8.35472068737837E-06"
        izz="0.000533386188926869" />
    </inertial>
    <visual>
      <origin
        xyz="0 0 0"
        rpy="0 0 0" />
      <geometry>
        <mesh
          filename="package://my_tf_tree/meshes/back_right_steering.obj" />
      </geometry>
      <material
        name="">
        <color
          rgba="0.647058823529412 0.619607843137255 0.588235294117647 1" />
      </material>
    </visual>
    <collision>
      <origin
        xyz="0 0 0"
        rpy="0 0 0" />
      <geometry>
        <mesh
          filename="package://my_tf_tree/meshes/back_right_steering.obj" />
      </geometry>
    </collision>
  </link>
  <joint
    name="back_right_steering_joint"
    type="continuous">
    <origin
      xyz="-0.23737 0.21658 0.01281"
      rpy="1.5708 0 2.6057" />
    <parent
      link="base_link" />
    <child
      link="back_right_steering" />
    <axis
      xyz="0 -1 0" />
  </joint>
  <link
    name="back_right_wheel">
    <inertial>
      <origin
        xyz="-1.36224666647533E-05 -0.00233860532400544 -1.27813299849455E-05"
        rpy="0 0 0" />
      <mass
        value="0.265552463932757" />
      <inertia
        ixx="0.000257423769631664"
        ixy="4.21536341431748E-07"
        ixz="6.90830608456542E-07"
        iyy="0.00042589263687006"
        iyz="3.86659897806611E-07"
        izz="0.000257304300299443" />
    </inertial>
    <visual>
      <origin
        xyz="0 0 0"
        rpy="0 0 0" />
      <geometry>
        <mesh
          filename="package://my_tf_tree/meshes/back_right_wheel.obj" />
      </geometry>
      <material
        name="">
        <color
          rgba="0.776470588235294 0.756862745098039 0.737254901960784 1" />
      </material>
    </visual>
    <collision>
      <origin
        xyz="0 0 0"
        rpy="0 0 0" />
      <geometry>
        <mesh
          filename="package://my_tf_tree/meshes/back_right_wheel.obj" />
      </geometry>
    </collision>
  </link>
  <joint
    name="back_right_wheel_joint"
    type="continuous">
    <origin
      xyz="-0.0087483 -0.041 -0.0021067"
      rpy="-2.9038 -0.11023 -1.5975" />
    <parent
      link="back_right_steering" />
    <child
      link="back_right_wheel" />
    <axis
      xyz="0 1 0" />
  </joint>
  <link
    name="back_left_steering">
    <inertial>
      <origin
        xyz="0.00801776215485611 -0.0117428465593348 0.000580924896310397"
        rpy="0 0 0" />
      <mass
        value="0.610591222034384" />
      <inertia
        ixx="0.000582629289495632"
        ixy="-4.99430083911262E-07"
        ixz="1.10358360622292E-05"
        iyy="0.00099110287153188"
        iyz="-8.35472068738683E-06"
        izz="0.000533386188926729" />
    </inertial>
    <visual>
      <origin
        xyz="0 0 0"
        rpy="0 0 0" />
      <geometry>
        <mesh
          filename="package://my_tf_tree/meshes/back_left_steering.obj" />
      </geometry>
      <material
        name="">
        <color
          rgba="0.647058823529412 0.619607843137255 0.588235294117647 1" />
      </material>
    </visual>
    <collision>
      <origin
        xyz="0 0 0"
        rpy="0 0 0" />
      <geometry>
        <mesh
          filename="package://my_tf_tree/meshes/back_left_steering.obj" />
      </geometry>
    </collision>
  </link>
  <joint
    name="back_left_steering_joint"
    type="continuous">
    <origin
      xyz="0.23463 0.21658 0.01281"
      rpy="1.5708 0 1.0349" />
    <parent
      link="base_link" />
    <child
      link="back_left_steering" />
    <axis
      xyz="0 -1 0" />
  </joint>
  <link
    name="back_left_wheel">
    <inertial>
      <origin
        xyz="-1.36224666647741E-05 -0.00233860532400532 -1.27813299848067E-05"
        rpy="0 0 0" />
      <mass
        value="0.265552463932757" />
      <inertia
        ixx="0.000257423769631664"
        ixy="4.21536341431804E-07"
        ixz="6.90830608456558E-07"
        iyy="0.00042589263687006"
        iyz="3.866598978063E-07"
        izz="0.000257304300299443" />
    </inertial>
    <visual>
      <origin
        xyz="0 0 0"
        rpy="0 0 0" />
      <geometry>
        <mesh
          filename="package://my_tf_tree/meshes/back_left_wheel.obj" />
      </geometry>
      <material
        name="">
        <color
          rgba="0.776470588235294 0.756862745098039 0.737254901960784 1" />
      </material>
    </visual>
    <collision>
      <origin
        xyz="0 0 0"
        rpy="0 0 0" />
      <geometry>
        <mesh
          filename="package://my_tf_tree/meshes/back_left_wheel.obj" />
      </geometry>
    </collision>
  </link>
  <joint
    name="back_left_wheel_joint"
    type="continuous">
    <origin
      xyz="-0.0087483 -0.041 -0.0021067"
      rpy="-2.9038 -0.11023 -1.5975" />
    <parent
      link="back_left_steering" />
    <child
      link="back_left_wheel" />
    <axis
      xyz="0 1 0" />
  </joint>
</robot>